<?xml version="1.0"?>
<robot name="task_des" xmlns:xacro="http://www.ros.org/wiki/xacro">>
  
  <xacro:include filename="$(find task_des)/urdf/task_des.gazebo" />

  <link name="base">
      <inertial>
          <mass value="10"/>
          <origin xyz="0.0 0.0 0.0" rpy="0.0 0.0 0.0"/>
          <inertia ixx="1" ixy="0.0" ixz="0.0" iyy="1" iyz="0.0" izz="1"/>
      </inertial>
      
      <visual>
        <origin xyz="0 0 0" rpy="0 0 0"/>
        <geometry>
            <box size="1 1 0.1"/>
        </geometry>
        <material name="blue"/>
      </visual>

      <collision>
        <origin xyz="0 0 0" rpy="0.0 0.0 0.0"/>
        <geometry>
            <box size="1 1 0.1"/>
        </geometry>
      </collision>
  </link>

  <link name="slider">
      <inertial>
          <mass value="2"/>
          <origin xyz="0.0 0.0 0.0" rpy="0.0 0.0 0.0"/>
          <inertia ixx="1" ixy="0.0" ixz="0.0" iyy="1" iyz="0.0" izz="1"/>
      </inertial>
      
      <visual>
        <origin xyz="0 0 0" rpy="0 0 0"/>
        <geometry>
            <box size="0.1 0.1 0.1"/>
        </geometry>
        <material name="orange"/>
      </visual>

      <collision>
        <origin xyz="0 0 0" rpy="0.0 0.0 0.0"/>
        <geometry>
            <box size="0.1 0.1 0.1"/>
        </geometry>
      </collision>
  </link>

  <joint name="joont" type="prismatic">
    <axis xyz="0 1 0"/>
    <limit effort="1000" lower="-0.4" upper="0.4" velocity="1" />
    <origin rpy="0 0 0" xyz="0 0 0.1" />
    <parent link="base"/>
    <child link="slider"/>
  </joint>

  <transmission name="trans_joont">
    <type>transmission_interface/SimpleTransmission</type>
    <joint name="joont">
        <hardwareInterface>hardware_interface/EffortJointInterface</hardwareInterface>
    </joint>
    <actuator name="motor_joont">
        <hardwareInterface>hardware_interface/EffortJointInterface</hardwareInterface>
        <mechanicalReduction>1</mechanicalReduction>
    </actuator>
  </transmission>

  <link name="camera">
    <collision>
      <origin xyz="0 0 0" rpy="0 0 0"/>
      <geometry>
        <box size=""/>
      </geometry>
    </collision>
    <visual>
      <origin xyz="0 0 0" rpy="0 0 0"/>
      <geometry>
        <box size="0.01 0.01 0.01"/>
      </geometry>
      <material name="green"/>
    </visual>
    <inertial>
      <mass value="0.1" />
      <origin xyz="0 0 0" rpy="0 0 0"/>
      <inertia ixx="0.1" ixy="0" ixz="0" iyy="0.1" iyz="0" izz="0.1" />
    </inertial>
  </link>

  <joint name="camera_joint" type="fixed">
    <axis xyz="1.0 0.0 0.0"/>
    <origin xyz="0.055 0 0" rpy="0 0 0"/>
    <parent link="slider"/>
    <child link="camera"/>
  </joint>

</robot>